<?xml version="1.0"?>
<robot xmlns:xacro="http://ros.org/wiki/xacro" name="swole_7">

  <xacro:property name="PI" value="3.1415926535897931" />

  <!-- Wheels -->
  <xacro:property name="wheel_radius" value="0.05" />
  <xacro:property name="wheel_height" value="0.05" />
  <xacro:property name="wheel_mass" value="0.4" /> <!-- in kg-->

<xacro:include filename="$(find swole_7)/urdf/base/swole_base.urdf.xacro" />


	<!-- BASE FOOTPRINT --> 
		
      <link name="base_footprint">
		  <visual>
			  <origin xyz="0 0 0.05" rpy="0 0 0" />
			  <geometry>
				 <box size="0.001 0.001 0.0001" />
			  </geometry>
        <material name="darkgrey">
         <color rgba="0.1 0.1 0.1 1"/>
       </material>
		  </visual>
		</link>

		<joint name="base_footprint_joint" type="fixed">
		  <origin xyz="0 0 ${wheel_radius}" rpy="0 0 0" /> 
      <!-- ${wheel_radius} property must be defined inside wheel description -->
		  <parent link="base_footprint"/>
		  <child link="base_link" />
		</joint> 

    <link
    name="base_link">
    <inertial>
      <origin
        xyz="-0.0148176230048584 0.00401001080732938 0.0686503041268495"
        rpy="0 0 0" />
     <mass
        value="0.43823834058655" />
      <inertia
        ixx="0.00314976311839575"
        ixy="-9.54850998275818E-19"
        ixz="-8.87078769442381E-22"
        iyy="0.00277373372724309"
        iyz="-5.06082384233403E-22"
        izz="0.00592055170139079" />
    </inertial>
    <visual>
      <origin
        xyz="0 0 0"
        rpy="0 0 0" />
      <geometry>
        <mesh
          filename="package://swole_7/meshes/base_link.STL" />
      </geometry>
      <material
        name="">
        <color
          rgba="0.792156862745098 0.819607843137255 0.933333333333333 1" />
      </material>
    </visual>
    <collision>
      <origin
        xyz="0 0 0"
        rpy="0 0 0" />
      <geometry>
        <mesh
          filename="package://swole_7/meshes/base_link.STL" />
      </geometry>
    </collision>
  </link>
  <link
    name="front_right_wheel">
    <inertial>
      <origin
        xyz="1.4481E-11 3.6689E-05 5.3453E-11"
        rpy="0 0 0" />
      <mass
        value="0.4" />
      <inertia
        ixx="5.541E-05"
        ixy="-4.7628E-15"
        ixz="-4.7607E-14"
        iyy="6.7546E-05"
        iyz="-3.3652E-14"
        izz="5.541E-05" />
    </inertial>
    <visual>
      <origin
        xyz="0 0 0"
        rpy="0 0 0" />
      <geometry>
        <mesh
          filename="package://swole_7/meshes/omni_wheel_1.dae" scale="0.4 0.4 0.4"/>
      </geometry>
      <material
        name="">
        <color
          rgba="0.79216 0.81961 0.93333 1" />
      </material>
    </visual>
    <collision>
      <origin
        xyz="0 0 0"
        rpy="1.57 0 0" />
        <geometry>
					<cylinder length="0.05" radius="0.05" />
        </geometry>
    </collision>
  </link>
  <joint
    name="front_right_wheel_joint"
    type="continuous">
    <origin
      xyz="0.10879 -0.20416 -0.035575"
      rpy="0 0 0" />
    <parent
      link="base_link" />
    <child
      link="front_right_wheel" />
    <axis
      xyz="0 1 0" />
     <limit effort="100" velocity="100"/>
    <joint_properties damping="0.0" friction="0.0"/>
  </joint>
  <link
    name="front_left_wheel">
    <inertial>
      <origin
        xyz="1.7206E-11 -6.0979E-12 4.367E-11"
        rpy="0 0 0" />
      <mass
        value="0.4" />
      <inertia
        ixx="5.541E-05"
        ixy="-1.8289E-14"
        ixz="1.6534E-13"
        iyy="6.7546E-05"
        iyz="4.9936E-14"
        izz="5.541E-05" />
    </inertial>
    <visual>
      <origin
        xyz="0 0 0"
        rpy="0 0 0" />
      <geometry>
        <mesh
          filename="package://swole_7/meshes/omni_wheel_2.dae" scale="0.4 0.4 0.4"/>
      </geometry>
      <material
        name="">
        <color
          rgba="0.79216 0.81961 0.93333 1" />
      </material>
    </visual>
    <collision>
      <origin
        xyz="0 0 0"
        rpy="1.57 0 0" />
        <geometry>
					<cylinder length="0.05" radius="0.05" />
        </geometry>
    </collision>
  </link>
  <joint
    name="front_left_wheel_joint"
    type="continuous">
    <origin
      xyz="0.099888 0.20438 -0.035575"
      rpy="0 0 0" />
    <parent
      link="base_link" />
    <child
      link="front_left_wheel" />
    <axis
      xyz="0 1 0" />
    <limit effort="100" velocity="100"/>
    <joint_properties damping="0.0" friction="0.0"/>
  </joint>
  <link
    name="rear_left_wheel">
    <inertial>
      <origin
        xyz="-1.8869E-11 -7.9625E-12 -1.3747E-12"
        rpy="0 0 0" />
      <mass
        value="0.4" />
      <inertia
        ixx="5.541E-05"
        ixy="1.182E-14"
        ixz="-1.164E-13"
        iyy="6.7546E-05"
        iyz="2.6018E-14"
        izz="5.541E-05" />
    </inertial>
    <visual>
      <origin
        xyz="0 0 0"
        rpy="0 0 0" />
      <geometry>
        <mesh
          filename="package://swole_7/meshes/omni_wheel_2.dae" scale="0.4 0.4 0.4"/>
      </geometry>
      <material
        name="">
        <color
          rgba="0.79216 0.81961 0.93333 1" />
      </material>
    </visual>
    <collision>
      <origin
        xyz="0 0 0"
        rpy="1.57 0 0" />
        <geometry>
					<cylinder length="0.05" radius="0.05" />
        </geometry>
    </collision>
  </link>
  <joint
    name="rear_left_wheel_joint"
    type="continuous">
    <origin
      xyz="-0.091212 0.20438 -0.035575"
      rpy="0 0 0" />
    <parent
      link="base_link" />
    <child
      link="rear_left_wheel" />
    <axis
      xyz="0 1 0" />
  </joint>
  <link
    name="rear_right_wheel">
    <inertial>
      <origin
        xyz="-1.4481E-11 3.6689E-05 -5.3453E-11"
        rpy="0 0 0" />
      <mass
        value="0.4" />
      <inertia
        ixx="5.541E-05"
        ixy="4.7618E-15"
        ixz="-4.7607E-14"
        iyy="6.7546E-05"
        iyz="3.3654E-14"
        izz="5.541E-05" />
    </inertial>
    <visual>
      <origin
        xyz="0 0 0"
        rpy="0 0 0" />
      <geometry>
        <mesh
          filename="package://swole_7/meshes/omni_wheel_1.dae" scale="0.4 0.4 0.4"/>
      </geometry>
      <material
        name="">
        <color
          rgba="0.79216 0.81961 0.93333 1" />
      </material>
    </visual>
    <collision>
      <origin
        xyz="0 0 0"
        rpy="1.57 0 0" />
        <geometry>
					<cylinder length="0.05" radius="0.05" />
        </geometry>
    </collision>
  </link>
  <joint
    name="rear_right_wheel_joint"
    type="continuous">
    <origin
      xyz="-0.090543 -0.20416 -0.035575"
      rpy="0 0 0" />
    <parent
      link="base_link" />
    <child
      link="rear_right_wheel" />
    <axis
      xyz="0 1 0" />
  </joint>
  <link
    name="gripper_lifter">
    <inertial>
      <origin
        xyz="-0.0249741085115004 0.00401001080732938 0.0686503041268495"
        rpy="0 0 0" />
      <mass
        value="0.0172" />
      <inertia
        ixx="0.00021296"
        ixy="-1.3863E-08"
        ixz="-1.1287E-14"
        iyy="0.00017198"
        iyz="-1.0274E-15"
        izz="0.00020319" />
    </inertial>
    <visual>
      <origin
        xyz="0 0 0"
        rpy="0 0 0" />
      <geometry>
        <mesh
          filename="package://swole_7/meshes/gripper_lifter.STL" />
      </geometry>
      <material
        name="">
        <color
          rgba="0.79216 0.81961 0.93333 1" />
      </material>
    </visual>
    <collision>
      <origin
        xyz="0 0 0"
        rpy="0 0 0" />
      <geometry>
        <mesh
          filename="package://swole_7/meshes/gripper_lifter.STL" />
      </geometry>
    </collision>
  </link>
  <joint
    name="gripper_lifter_joint"
    type="prismatic">
    <origin
      xyz="-0.0249741085115004 0.00401001080732938 0.0686503041268495"
      rpy="0 0 0" />
    <parent
      link="base_link" />
    <child
      link="gripper_lifter" />
    <axis
      xyz="0 0 1" />
      <!-- stroke length 0.1524 m -->
    <!-- <limit velocity="1.0" effort="10.0" lower="0.0686503041268495" upper="0"/> -->
    <limit velocity="1.0" effort="10.0" lower="0" upper="${0.0686503041268495 + 0.2524}"/>
    <dynamics friction="1" damping="1" />
  </joint>
  <link
    name="lidar_plate">
    <inertial>
      <origin
        xyz="0 -2.7756E-17 -5.5511E-17"
        rpy="0 0 0" />
      <mass
        value="0.00000019609" />
      <inertia
        ixx="6.9293E-06"
        ixy="-1.434E-21"
        ixz="-7.3447E-22"
        iyy="2.3202E-05"
        iyz="3.4914E-23"
        izz="3.0098E-05" />
    </inertial>
    <visual>
      <origin
        xyz="0 0 0"
        rpy="0 0 0" />
      <geometry>
        <mesh
          filename="package://swole_7/meshes/lidar_plate.STL" />
      </geometry>
      <material
        name="">
        <color
          rgba="0.79216 0.81961 0.93333 1" />
      </material>
    </visual>
    <collision>
      <origin
        xyz="0 0 0"
        rpy="0 0 0" />
      <geometry>
        <mesh
          filename="package://swole_7/meshes/lidar_plate.STL" />
      </geometry>
    </collision>
  </link>
  <joint
    name="lidar_plate_joint"
    type="fixed">
    <origin
      xyz="0.035612 0 0.15559"
      rpy="0 0 0" />
    <parent
      link="gripper_lifter" />
    <child
      link="lidar_plate" />
    <axis
      xyz="0 0 1" />
  </joint>

  <!-- Lidar -->
  <joint name="lidar_joint" type="fixed">
    <axis xyz="0 1 0" />
    <origin xyz="0 0 0" rpy="0 0 0"/>
    <parent link="lidar_plate"/>
    <child link="lidar"/>
  </joint>

  <!-- Hokuyo Laser -->
  <link name="lidar">
    <collision>
      <origin xyz="0 0 0" rpy="0 0 0"/>
      <geometry>
    <box size="0.1 0.1 0.1"/>
      </geometry>
    </collision>
    <visual>
      <origin xyz="0.01 0 0.03" rpy="0 0 0"/>
        <geometry>
					<cylinder length="0.04" radius="0.06" />
        </geometry>
    </visual>
    <inertial>
      <mass value="1e-5" />
      <origin xyz="0 0 0" rpy="0 0 0"/>
      <inertia ixx="1e-6" ixy="0" ixz="0" iyy="1e-6" iyz="0" izz="1e-6" />
    </inertial>
  </link>
  <link
    name="finger_right">
    <inertial>
      <origin
        xyz="-5.5511E-17 1.3878E-17 5.5511E-17"
        rpy="0 0 0" />
      <mass
        value="0.0041334" />
      <inertia
        ixx="2.2294E-07"
        ixy="-1.2445E-24"
        ixz="1.0627E-22"
        iyy="1.2703E-06"
        iyz="-2.8075E-24"
        izz="1.0543E-06" />
    </inertial>
    <visual>
      <origin
        xyz="0 0 0"
        rpy="0 0 0" />
      <geometry>
        <mesh
          filename="package://swole_7/meshes/finger_right.STL" />
      </geometry>
      <material
        name="">
        <color
          rgba="0.79216 0.81961 0.93333 1" />
      </material>
    </visual>
    <collision>
      <origin
        xyz="0 0 0"
        rpy="0 0 0" />
      <geometry>
        <mesh
          filename="package://swole_7/meshes/finger_right.STL" />
      </geometry>
    </collision>
  </link>
  <joint
    name="finger_right_joint"
    type="prismatic">
    <origin
      xyz="0.2055 -0.054841 0.080876"
      rpy="0 0 0" />
    <parent
      link="gripper_lifter" />
    <child
      link="finger_right" />
    <axis
      xyz="0 0 1" />
    <limit
      lower="0"
      upper="0"
      effort="0"
      velocity="0" />
  </joint>
  <link
    name="load_cell_right">
    <inertial>
      <origin
        xyz="0 -2.7756E-17 -2.7756E-17"
        rpy="0 0 0" />
      <mass
        value="0.012334" />
      <inertia
        ixx="3.3867E-07"
        ixy="-4.5654E-20"
        ixz="-1.326E-21"
        iyy="6.5905E-06"
        iyz="3.1041E-23"
        izz="6.5834E-06" />
    </inertial>
    <visual>
      <origin
        xyz="0 0 0"
        rpy="0 0 0" />
      <geometry>
        <mesh
          filename="package://swole_7/meshes/load_cell_right.STL" />
      </geometry>
      <material
        name="">
        <color
          rgba="0.54902 0.18039 0.18039 1" />
      </material>
    </visual>
    <collision>
      <origin
        xyz="0 0 0"
        rpy="0 0 0" />
      <geometry>
        <mesh
          filename="package://swole_7/meshes/load_cell_right.STL" />
      </geometry>
    </collision>
  </link>
  <joint
    name="load_cell_right_joint"
    type="fixed">
    <origin
      xyz="-0.01482 0.014288 0"
      rpy="0 0 0" />
    <parent
      link="finger_right" />
    <child
      link="load_cell_right" />
    <axis
      xyz="0 0 1" />
  </joint>
  <link
    name="contact_right">
    <inertial>
      <origin
        xyz="-1.1102E-16 0.0028274 -2.7756E-17"
        rpy="0 0 0" />
      <mass
        value="0.019736" />
      <inertia
        ixx="1.407E-06"
        ixy="-4.8601E-20"
        ixz="2.4258E-22"
        iyy="7.9682E-06"
        iyz="-8.9801E-24"
        izz="6.6549E-06" />
    </inertial>
    <visual>
      <origin
        xyz="0 0 0"
        rpy="0 0 0" />
      <geometry>
        <mesh
          filename="package://swole_7/meshes/contact_right.STL" />
      </geometry>
      <material
        name="">
        <color
          rgba="0.29804 0.29804 0.29804 1" />
      </material>
    </visual>
    <collision>
      <origin
        xyz="0 0 0"
        rpy="0 0 0" />
      <geometry>
        <mesh
          filename="package://swole_7/meshes/contact_right.STL" />
      </geometry>
    </collision>
  </link>
  <joint
    name="contact_right_joint"
    type="fixed">
    <origin
      xyz="-0.04202 0.022225 0"
      rpy="0 0 0" />
    <parent
      link="finger_right" />
    <child
      link="contact_right" />
    <axis
      xyz="0 0 1" />
  </joint>
  <link
    name="finger_left">
    <inertial>
      <origin
        xyz="0 -2.7756E-17 2.7756E-17"
        rpy="0 0 0" />
      <mass
        value="0.0041334" />
      <inertia
        ixx="2.2294E-07"
        ixy="-1.0833E-24"
        ixz="8.7052E-23"
        iyy="1.2703E-06"
        iyz="-1.5725E-24"
        izz="1.0543E-06" />
    </inertial>
    <visual>
      <origin
        xyz="0 0 0"
        rpy="0 0 0" />
      <geometry>
        <mesh
          filename="package://swole_7/meshes/finger_left.STL" />
      </geometry>
      <material
        name="">
        <color
          rgba="0.79216 0.81961 0.93333 1" />
      </material>
    </visual>
    <collision>
      <origin
        xyz="0 0 0"
        rpy="0 0 0" />
      <geometry>
        <mesh
          filename="package://swole_7/meshes/finger_left.STL" />
      </geometry>
    </collision>
  </link>
  <joint
    name="finger_left_joint"
    type="prismatic">
    <origin
      xyz="0.20577 0.054684 0.080876"
      rpy="0 0 0" />
    <parent
      link="gripper_lifter" />
    <child
      link="finger_left" />
    <axis
      xyz="0 0 1" />
    <limit
      lower="0"
      upper="0"
      effort="0"
      velocity="0" />
  </joint>
  <link
    name="load_cell_left">
    <inertial>
      <origin
        xyz="0 -2.7756E-17 0"
        rpy="0 0 0" />
      <mass
        value="0.012334" />
      <inertia
        ixx="3.3867E-07"
        ixy="-9.5607E-22"
        ixz="-1.1726E-21"
        iyy="6.5905E-06"
        iyz="-6.4043E-24"
        izz="6.5834E-06" />
    </inertial>
    <visual>
      <origin
        xyz="0 0 0"
        rpy="0 0 0" />
      <geometry>
        <mesh
          filename="package://swole_7/meshes/load_cell_left.STL" />
      </geometry>
      <material
        name="">
        <color
          rgba="0.54902 0.18039 0.18039 1" />
      </material>
    </visual>
    <collision>
      <origin
        xyz="0 0 0"
        rpy="0 0 0" />
      <geometry>
        <mesh
          filename="package://swole_7/meshes/load_cell_left.STL" />
      </geometry>
    </collision>
  </link>
  <joint
    name="load_cell_left_joint"
    type="prismatic">
    <origin
      xyz="-0.01482 -0.014288 0"
      rpy="0 0 0" />
    <parent
      link="finger_left" />
    <child
      link="load_cell_left" />
    <axis
      xyz="0 0 1" />
    <limit
      lower="0"
      upper="0"
      effort="0"
      velocity="0" />
  </joint>
  <link
    name="contact_left">
    <inertial>
      <origin
        xyz="5.5511E-17 -0.0028274 2.7756E-17"
        rpy="0 0 0" />
      <mass
        value="0.019736" />
      <inertia
        ixx="1.407E-06"
        ixy="-2.1715E-21"
        ixz="-2.6305E-21"
        iyy="7.9682E-06"
        iyz="-1.8064E-23"
        izz="6.6549E-06" />
    </inertial>
    <visual>
      <origin
        xyz="0 0 0"
        rpy="0 0 0" />
      <geometry>
        <mesh
          filename="package://swole_7/meshes/contact_left.STL" />
      </geometry>
      <material
        name="">
        <color
          rgba="0.79216 0.81961 0.93333 1" />
      </material>
    </visual>
    <collision>
      <origin
        xyz="0 0 0"
        rpy="0 0 0" />
      <geometry>
        <mesh
          filename="package://swole_7/meshes/contact_left.STL" />
      </geometry>
    </collision>
  </link>
  <joint
    name="contact_left_joint"
    type="prismatic">
    <origin
      xyz="-0.04202 -0.022225 0"
      rpy="0 0 0" />
    <parent
      link="finger_left" />
    <child
      link="contact_left" />
    <axis
      xyz="0 0 1" />
    <limit
      lower="0"
      upper="0"
      effort="0"
      velocity="0" />
  </joint>


       <!-- Transmission is important to link the joints and the controller (see swole_xl_control/config/swole_xl_control.yaml)-->
    <transmission name="rear_left_wheel_joint_trans">
      <type>transmission_interface/SimpleTransmission</type>
      <joint name="rear_left_wheel_joint" >
        <hardwareInterface>hardware_interface/VelocityJointInterface</hardwareInterface>
      </joint>
      <actuator name="rear_left_wheel_joint_motor">
         <mechanicalReduction>1</mechanicalReduction>
      </actuator>
    </transmission>

    <gazebo reference="rear_left_wheel">
		<mu1 value="1.0"/>
		<mu2 value="1.0"/>
		<kp value="10000000.0" />
		<kd value="1.0" />
		<fdir1 value="1 0 0"/>
        <turnGravityOff>false</turnGravityOff>
    </gazebo>

       <!-- Transmission is important to link the joints and the controller (see swole_xl_control/config/swole_xl_control.yaml)-->
    <transmission name="front_right_wheel_joint_trans">
      <type>transmission_interface/SimpleTransmission</type>
      <joint name="front_right_wheel_joint" >
        <hardwareInterface>hardware_interface/VelocityJointInterface</hardwareInterface>
      </joint>
      <actuator name="front_right_wheel_joint_motor">
         <mechanicalReduction>1</mechanicalReduction>
      </actuator>
    </transmission>

    <gazebo reference="front_right_wheel">
		<mu1 value="1.0"/>
		<mu2 value="1.0"/>
		<kp value="10000000.0" />
		<kd value="1.0" />
		<fdir1 value="1 0 0"/>
        <turnGravityOff>false</turnGravityOff>
    </gazebo>


       <!-- Transmission is important to link the joints and the controller (see swole_xl_control/config/swole_xl_control.yaml)-->
    <transmission name="front_left_wheel_joint_trans">
      <type>transmission_interface/SimpleTransmission</type>
      <joint name="front_left_wheel_joint" >
        <hardwareInterface>hardware_interface/VelocityJointInterface</hardwareInterface>
      </joint>
      <actuator name="front_left_wheel_joint_motor">
         <mechanicalReduction>1</mechanicalReduction>
      </actuator>
    </transmission>

    <gazebo reference="front_left_wheel">
		<mu1 value="1.0"/>
		<mu2 value="1.0"/>
		<kp value="10000000.0" />
		<kd value="1.0" />
		<fdir1 value="1 0 0"/>
        <turnGravityOff>false</turnGravityOff>
    </gazebo>



    <!-- Gripper -->
    <transmission name="gripper_lifter_tr">
        <type>transmission_interface/SimpleTransmission</type>
        <joint name="gripper_lifter_joint">
           <hardwareInterface>hardware_interface/EffortJointInterface</hardwareInterface>
        </joint>
        <actuator name="motor_gripper_lifter_joint">
           <hardwareInterface>hardware_interface/EffortJointInterface</hardwareInterface>
          <mechanicalReduction>1</mechanicalReduction>
        </actuator>
      </transmission>

          <!-- hokuyo -->
  <gazebo reference="lidar">
    <sensor type="gpu_ray" name="head_hokuyo_sensor">
      <pose>0 0 0 0 0 0</pose>
      <visualize>true</visualize>
      <update_rate>6</update_rate>
      <ray>
        <scan>
          <horizontal>
            <samples>720</samples>
            <resolution>1</resolution>
            <min_angle>-3.14</min_angle>
            <max_angle>3.14</max_angle>
          </horizontal>
        </scan>
        <range>
          <min>0.15</min>
          <max>8.0</max>
          <resolution>0.01</resolution>
        </range>
        <noise>
          <type>gaussian</type>
          <!-- Noise parameters based on published spec for Hokuyo laser
               achieving "+-30mm" accuracy at range < 10m.  A mean of 0.0m and
               stddev of 0.01m will put 99.7% of samples within 0.03m of the true
               reading. -->
          <mean>0.0</mean>
          <stddev>0.01</stddev>
        </noise>
      </ray>
      <plugin name="gazebo_ros_head_hokuyo_controller" filename="libgazebo_ros_gpu_laser.so">
        <topicName>/swole/laser/scan</topicName>
        <frameName>lidar</frameName>
      </plugin>
    </sensor>
  </gazebo>

  <gazebo>
    <plugin name="imu_plugin" filename="libgazebo_ros_imu.so">
      <alwaysOn>true</alwaysOn>
      <bodyName>base_footprint</bodyName>
      <topicName>imu</topicName>
      <serviceName>imu_service</serviceName>
      <gaussianNoise>0.0</gaussianNoise>
      <updateRate>20.0</updateRate>
    </plugin>
  </gazebo>

  <!-- Ros control plugin -->
  <gazebo>
  <plugin name="gazebo_ros_control" filename="libgazebo_ros_control.so">
    <robotNamespace>/swole_7</robotNamespace>
  </plugin>
</gazebo>
  
</robot>